<?xml version="1.0"?>
<robot name="trobo">
  <link name="world"/>
  <joint name="fixed" type="fixed">
    <parent link="world"/>
    <child link="link1"/> 
  </joint>

  <!-- base_link -->
  <link name="link1">
    <collision>
      <origin xyz="0 0 0.5" rpy="0 0 0"/>
      <geometry>
        <box size="0.1 0.1 1.0"/>
      </geometry>
    </collision>

    <inertial>
      <origin xyz="0 0 0.5" rpy="0 0 0"/>
      <mass value="1.0"/>
      <inertia ixx="1.0" ixy="0.0" ixz="0.0" iyy="1.0" iyz="0.0" izz="1.0"/>
    </inertial>
    
    <visual>
      <origin xyz="0 0 0.5" rpy="0 0 0"/>
      <geometry>
        <box size="0.1 0.1 1.0"/>
      </geometry>
    </visual>
  </link>

  <gazebo reference="link1">
    <material>Gazebo/Red</material>
  </gazebo>


  <!-- joint1 -->
  <joint name="joint1" type="continuous">
    <parent link="link1"/>
    <child link="link2"/>
    <axis xyz="0 1 0"/>
    <origin xyz="0 0.1 1.0" rpy="0 0 0"/>
    <dynamics damping="0.7"/>
  </joint>
  

  <!-- Middle Link -->
  <link name="link2">
    <collision>
      <origin xyz="0 0 0.25" rpy="0 0 0"/>
      <geometry>
        <box size="0.1 0.1 0.5"/>
      </geometry>
    </collision>

    <visual>
      <origin xyz="0 0 0.25" rpy="0 0 0"/>
      <geometry>
        <box size="0.1 0.1 0.5"/>
      </geometry>
    </visual>

    <inertial>
      <mass value="1.0"/>
      <origin xyz="0 0 0.25" rpy="0 0 0"/>
      <inertia ixx="1.0" ixy="0.0" ixz="0.0" iyy="1.0" iyz="0.0" izz="1.0"/>
    </inertial>
  </link>

  <transmission name="tran1">
    <type>transmission_interface/SimpleTransmission</type>
    <joint name="joint1">
      <hardwareInterface>hardware_interface/PositionJointInterface</hardwareInterface>
    </joint>
    <actuator name="motor1">
       <hardwareInterface>hardware_interface/PositionJointInterface</hardwareInterface>
       <mechanismReduction>1</mechanismReduction>
    </actuator>
  </transmission>

  <gazebo>
    <plugin name="gazebo_ros_control" filename="libgazebo_ros_control.so">
      <!--<robotNamespace>/trobo</robotNamespace>-->
      <!--<controlPeriod>0.001</controlPeriod>-->
    </plugin>
  </gazebo>
</robot>